Workbook

Sheet DB WBS
A1: Budidaya | B1: Plant | C1: Desc. | D1: Period | E1: Aktifitas | F1: Job Name | G1: Cost Element | H1: Cost Element Desc | I1: Klasifikasi | J1: Nilai | K1: Fisik
A2: KR | B2: 5E06 | C2: KEBUN SINTANG | D2: 1 | E2: 60-03 | F2: SADAP (ATS) | G2: 51101056 | H2: Biaya Panen | I2: 2. SPK | J2: 4158000 | K2: 594
A3: KR | B3: 5E06 | C3: KEBUN SINTANG | D3: 1 | E3: 60-03 | F3: SADAP (ATS) | G3: 90043001 | H3: Activity Type E-LBR | I3: 1. Gaji | J3: 28453544 | K3: 184
A4: KR | B4: 5E06 | C4: KEBUN SINTANG | D4: 1 | E4: 90-03 | G4: 90042014 | H4: Assessment Panen | I4: 1. Gaji | J4: 39212995 | K4: 0
A5: KR | B5: 5E06 | C5: KEBUN SINTANG | D5: 1 | E5: 99-01 | G5: 90042012 | H5: Assessment Karpim | I5: 1. Gaji | J5: 23330439 | K5: 0
A6: KR | B6: 5E06 | C6: KEBUN SINTANG | D6: 1 | E6: 99-01 | G6: 90042121 | H6: Assessment BTL - Keamanan | I6: 6.Lain-Lain | J6: 40967991 | K6: 0
A7: KR | B7: 5E06 | C7: KEBUN SINTANG | D7: 1 | E7: 99-01 | G7: 90042125 | H7: Assessment BTL-Gaji&Tunjangan Karpim | I7: 6.Lain-Lain | J7: 11116981 | K7: 0
A8: KR | B8: 5E06 | C8: KEBUN SINTANG | D8: 1 | E8: 99-01 | G8: 90042127 | H8: Assessment BTL-Pemeliharaan Bangunan Per | I8: 6.Lain-Lain | J8: 3175000 | K8: 0
A9: KR | B9: 5E06 | C9: KEBUN SINTANG | D9: 1 | E9: 99-01 | G9: 90042132 | H9: Assessment BTL-Pemeliharaan Bangunan Rum | I9: 6.Lain-Lain | J9: 373000 | K9: 0
A10: KR | B10: 5E06 | C10: KEBUN SINTANG | D10: 1 | E10: 99-01 | G10: 90042134 | H10: Assessment BTL- Pemeliharaan Alat Invent | I10: 6.Lain-Lain | J10: 500000 | K10: 0
A11: KR | B11: 5E06 | C11: KEBUN SINTANG | D11: 1 | E11: 99-01 | G11: 90042135 | H11: Assessment BTL-Gaji, Upah & Tunj Karpel | I11: 6.Lain-Lain | J11: 5468500 | K11: 0
A12: KR | B12: 5E06 | C12: KEBUN SINTANG | D12: 1 | E12: 99-01 | G12: 90042126 | H12: Assessment BTL- Pengangkutan | I12: 6.Lain-Lain | J12: 6766136 | K12: 0
A13: KR | B13: 5E13 | C13: KEBUN BATULICIN | D13: 1 | E13: 53-07 | F13: STRIP WEEDING CHEMIS | G13: 51100058 | H13: Bi Konsumsi Persediaan Pupuk dan Herbisi | I13: 3. Bahan | J13: 17619625 | K13: 265.755
A14: KR | B14: 5E13 | C14: KEBUN BATULICIN | D14: 1 | E14: 53-07 | F14: STRIP WEEDING CHEMIS | G14: 51100651 | H14: Biaya Pemeliharaan Aset Tanaman | I14: 6.Lain-Lain | J14: 0 | K14: 0
A15: KR | B15: 5E13 | C15: KEBUN BATULICIN | D15: 1 | E15: 53-07 | F15: STRIP WEEDING CHEMIS | G15: 51100774 | H15: Biaya Borongan | I15: 2. SPK | J15: 22490300 | K15: 332.5
A16: KR | B16: 5E13 | C16: KEBUN BATULICIN | D16: 1 | E16: 55-08 | F16: STIMULANSIA | G16: 51100061 | H16: Bi Konsumsi Persediaan Bahan Kimia | I16: 3. Bahan | J16: 3830989 | K16: 177
A17: KR | B17: 5E13 | C17: KEBUN BATULICIN | D17: 1 | E17: 60-02 | F17: PENYADAPAN DTS (D3) | G17: 51101056 | H17: Biaya Panen | I17: 2. SPK | J17: 290911375 | K17: 54040.5
A18: KR | B18: 5E13 | C18: KEBUN BATULICIN | D18: 1 | E18: 60-02 | F18: PENYADAPAN DTS (D3) | G18: 90043001 | H18: Activity Type E-LBR | I18: 1. Gaji | J18: 20462790 | K18: 110.5
A19: KR | B19: 5E13 | C19: KEBUN BATULICIN | D19: 1 | E19: 60-03 | F19: SADAP (ATS) | G19: 51101056 | H19: Biaya Panen | I19: 2. SPK | J19: 9764000 | K19: 1376
A20: KR | B20: 5E13 | C20: KEBUN BATULICIN | D20: 1 | E20: 60-05 | F20: PENGANGKUTAN KE TPH | G20: 51101056 | H20: Biaya Panen | I20: 2. SPK | J20: 11165736 | K20: 11817.45
A21: KR | B21: 5E13 | C21: KEBUN BATULICIN | D21: 1 | E21: 60-05 | F21: PENGANGKUTAN KE TPH | G21: 90043001 | H21: Activity Type E-LBR | I21: 1. Gaji | J21: 6811521 | K21: 37.5
A22: KR | B22: 5E13 | C22: KEBUN BATULICIN | D22: 1 | E22: 60-08 | F22: PENGANGKUTAN KOMPO-CUPLUMP | G22: 90043002 | H22: Activity Type E-KM | I22: 4. EAP | J22: 29406569 | K22: 2495
A23: KR | B23: 5E13 | C23: KEBUN BATULICIN | D23: 1 | E23: 60-18 | F23: TM PEMASANGAN RAIN GUARD | G23: 51100064 | H23: Bi Konsumsi Kebutuhan Operasional | I23: 3. Bahan | J23: 38661 | K23: 300
A24: KR | B24: 5E13 | C24: KEBUN BATULICIN | D24: 1 | E24: 90-01 | G24: 90042011 | H24: Assessment Pemeliharaan | I24: 1. Gaji | J24: 29241773 | K24: 0
A25: KR | B25: 5E13 | C25: KEBUN BATULICIN | D25: 1 | E25: 90-03 | G25: 90042014 | H25: Assessment Panen | I25: 1. Gaji | J25: 162694136 | K25: 0
A26: KR | B26: 5E13 | C26: KEBUN BATULICIN | D26: 1 | E26: 99-01 | G26: 90042012 | H26: Assessment Karpim | I26: 1. Gaji | J26: 67520241 | K26: 0
A27: KR | B27: 5E13 | C27: KEBUN BATULICIN | D27: 1 | E27: 99-01 | G27: 90042121 | H27: Assessment BTL - Keamanan | I27: 6.Lain-Lain | J27: 81268406 | K27: 0
A28: KR | B28: 5E13 | C28: KEBUN BATULICIN | D28: 1 | E28: 99-01 | G28: 90042122 | H28: Assessment Penerangan | I28: 6.Lain-Lain | J28: 1048000 | K28: 0
A29: KR | B29: 5E13 | C29: KEBUN BATULICIN | D29: 1 | E29: 99-01 | G29: 90042124 | H29: Assessment BTL- Pemeliharaan Jalan | I29: 6.Lain-Lain | J29: 13432000 | K29: 0
A30: KR | B30: 5E13 | C30: KEBUN BATULICIN | D30: 1 | E30: 99-01 | G30: 90042125 | H30: Assessment BTL-Gaji&Tunjangan Karpim | I30: 6.Lain-Lain | J30: 47163768 | K30: 0
A31: KR | B31: 5E13 | C31: KEBUN BATULICIN | D31: 1 | E31: 99-01 | G31: 90042127 | H31: Assessment BTL-Pemeliharaan Bangunan Per | I31: 6.Lain-Lain | J31: 15608302 | K31: 0
A32: KR | B32: 5E13 | C32: KEBUN BATULICIN | D32: 1 | E32: 99-01 | G32: 90042128 | H32: Assessment BTL- Air | I32: 6.Lain-Lain | J32: 748000 | K32: 0
A33: KR | B33: 5E13 | C33: KEBUN BATULICIN | D33: 1 | E33: 99-01 | G33: 90042132 | H33: Assessment BTL-Pemeliharaan Bangunan Rum | I33: 6.Lain-Lain | J33: 6413600 | K33: 0
A34: KR | B34: 5E13 | C34: KEBUN BATULICIN | D34: 1 | E34: 99-01 | G34: 90042134 | H34: Assessment BTL- Pemeliharaan Alat Invent | I34: 6.Lain-Lain | J34: 1617500 | K34: 0
A35: KR | B35: 5E13 | C35: KEBUN BATULICIN | D35: 1 | E35: 99-01 | G35: 90042135 | H35: Assessment BTL-Gaji, Upah & Tunj Karpel | I35: 6.Lain-Lain | J35: 71515047 | K35: 0
... A42: KR | B42: 5E13 | C42: KEBUN BATULICIN | D42: 1 | E42: 99-01 | G42: 90042126 | H42: Assessment BTL- Pengangkutan | I42: 6.Lain-Lain | J42: 33176702 | K42: 0
A43: KR | B43: 5E19 | C43: KEBUN LONGKALI | D43: 1 | E43: 60-04 | F43: SERAP SADAP | G43: 51101056 | H43: Biaya Panen | I43: 2. SPK | J43: 2697368 | K43: 193
A44: KR | B44: 5E19 | C44: KEBUN LONGKALI | D44: 1 | E44: 60-07 | F44: PENGANGKUTAN LATEX | G44: 51100153 | H44: Biaya Jasa Transportasi - Non Penjualan | I44: 2. SPK | J44: 362400 | K44: 604
A45: KR | B45: 5E19 | C45: KEBUN LONGKALI | D45: 1 | E45: 99-01 | G45: 90042121 | H45: Assessment BTL - Keamanan | I45: 6.Lain-Lain | J45: 6508171 | K45: 0
A46: KR | B46: 5E19 | C46: KEBUN LONGKALI | D46: 1 | E46: 99-01 | G46: 90042135 | H46: Assessment BTL-Gaji, Upah & Tunj Karpel | I46: 6.Lain-Lain | J46: 8539632 | K46: 0
...

Sheet DB GC
A1: Uraian | B1: Plant | C1: Unit Kerja | D1: Period | E1: GC | F1: Cost Element | G1: Cost element name | H1: Klasifikasi | I1: Nilai
A2: KR | B2: 5E06 | C2: KEBUN SINTANG | D2: 1 | E2: GC Panen | F2: 90042077 | G2: Asst. Premi Panen | H2: 1. Gaji | I2: 1890000
A3: KR | B3: 5E06 | C3: KEBUN SINTANG | D3: 1 | E3: GC Panen | F3: 90043001 | G3: Act Type E-LBR | H3: 1. Gaji | I3: 16354812
A4: KR | B4: 5E06 | C4: KEBUN SINTANG | D4: 1 | E4: GC Panen | F4: 90043000 | G4: Act Type E-SPV | H4: 1. Gaji | I4: 19410058
A5: KR | B5: 5E06 | C5: KEBUN SINTANG | D5: 1 | E5: GC Panen | F5: 51100402 | G5: Honorarium/Upah | H5: 1. Gaji | I5: 1558125
A6: KR | B6: 5E13 | C6: KEBUN BATULICIN | D6: 1 | E6: GC Panen | F6: 51100064 | G6: Bi Konsumsi Kebut Op | H6: 3. Bahan | I6: 1618482
A7: KR | B7: 5E13 | C7: KEBUN BATULICIN | D7: 1 | E7: GC Panen | F7: 51100441 | G7: BPJS TK - Jaminan Ke | H7: 1. Gaji | I7: 764640
A8: KR | B8: 5E13 | C8: KEBUN BATULICIN | D8: 1 | E8: GC Panen | F8: 51100442 | G8: BPJS TK - Jaminan Ke | H8: 1. Gaji | I8: 424800
A9: KR | B9: 5E13 | C9: KEBUN BATULICIN | D9: 1 | E9: GC Panen | F9: 90042077 | G9: Asst. Premi Panen | H9: 1. Gaji | I9: 21924449
A10: KR | B10: 5E13 | C10: KEBUN BATULICIN | D10: 1 | E10: GC Panen | F10: 90043001 | G10: Act Type E-LBR | H10: 1. Gaji | I10: 20942872
A11: KR | B11: 5E13 | C11: KEBUN BATULICIN | D11: 1 | E11: GC Panen | F11: 90043000 | G11: Act Type E-SPV | H11: 1. Gaji | I11: 117018893
A12: KR | B12: 5E13 | C12: KEBUN BATULICIN | D12: 1 | E12: GC Pemel | F12: 90043000 | G12: Act Type E-SPV | H12: 1. Gaji | I12: 29241773
A13: KS | B13: 5E01 | C13: KEBUN GUNUNG MELIAU | D13: 1 | E13: GC Angkut | F13: 90042084 | G13: Asst Premi Pnggkutan | H13: 1. Gaji | I13: 3680415
... A159: KS | B159: 5E01 | C159: KEBUN GUNUNG MELIAU | D159: 2 | E159: GC Pemel | F159: 51100063 | G159: Bi Kons Pers Suku Ca | H159: 6.Lain-Lain | I159: 444000
A160: KS | B160: 5E01 | C160: KEBUN GUNUNG MELIAU | D160: 2 | E160: #N/A | F160: 51100608 | G160: Bi Keamanan | H160: 2. SPK | I160: 146839134
A161: KS | B161: 5E01 | C161: KEBUN GUNUNG MELIAU | D161: 2 | E161: #N/A | F161: 51100608 | G161: Bi Keamanan | H161: 6.Lain-Lain | I161: -48946378
A162: KS | B162: 5E02 | C162: KEBUN GUNUNG MAS | D162: 2 | E162: GC Angkut | F162: 90042084 | G162: Asst Premi Pnggkutan | H162: 1. Gaji | I162: 6018700
A163: KS | B163: 5E02 | C163: KEBUN GUNUNG MAS | D163: 2 | E163: GC Angkut | F163: 90043001 | G163: Act Type E-LBR | H163: 1. Gaji | I163: 5149908
A164: KS | B164: 5E02 | C164: KEBUN GUNUNG MAS | D164: 2 | E164: GC Angkut | F164: 90043000 | G164: Act Type E-SPV | H164: 1. Gaji | I164: 7462728
A165: KS | B165: 5E02 | C165: KEBUN GUNUNG MAS | D165: 2 | E165: GC Panen | F165: 51100064 | G165: Bi Konsumsi Kebut Op | H165: 3. Bahan | I165: 120000
A166: KS | B166: 5E02 | C166: KEBUN GUNUNG MAS | D166: 2 | E166: GC Panen | F166: 51100064 | G166: Bi Konsumsi Kebut Op | H166: 6.Lain-Lain | I166: 1280000
A167: KS | B167: 5E02 | C167: KEBUN GUNUNG MAS | D167: 2 | E167: GC Panen | F167: 90042077 | G167: Asst. Premi Panen | H167: 1. Gaji | I167: 37422262
A168: KS | B168: 5E02 | C168: KEBUN GUNUNG MAS | D168: 2 | E168: GC Panen | F168: 90043001 | G168: Act Type E-LBR | H168: 1. Gaji | I168: 204833030
A169: KS | B169: 5E02 | C169: KEBUN GUNUNG MAS | D169: 2 | E169: GC Panen | F169: 90043000 | G169: Act Type E-SPV | H169: 1. Gaji | I169: 130518159
A170: KS | B170: 5E02 | C170: KEBUN GUNUNG MAS | D170: 2 | E170: GC Pemel | F170: 51100401 | G170: Bi Gaji dan Tunjanga | H170: 1. Gaji | I170: 16200300
A171: KS | B171: 5E02 | C171: KEBUN GUNUNG MAS | D171: 2 | E171: GC Pemel | F171: 90042080 | G171: Ast. Premi Pemel TBM | H171: 6.Lain-Lain | I171: 10945035
A172: KS | B172: 5E02 | C172: KEBUN GUNUNG MAS | D172: 2 | E172: GC Pemel | F172: 90043001 | G172: Act Type E-LBR | H172: 1. Gaji | I172: 230410437
A173: KS | B173: 5E02 | C173: KEBUN GUNUNG MAS | D173: 2 | E173: GC Pemel | F173: 90043000 | G173: Act Type E-SPV | H173: 1. Gaji | I173: 48894875
A174: KS | B174: 5E02 | C174: KEBUN GUNUNG MAS | D174: 2 | E174: #N/A | F174: 51100401 | G174: Bi Gaji dan Tunjanga | H174: 1. Gaji | I174: 14391378
A175: KS | B175: 5E02 | C175: KEBUN GUNUNG MAS | D175: 2 | E175: #N/A | F175: 51100608 | G175: Bi Keamanan | H175: 2. SPK | I175: 266333226
A176: KS | B176: 5E02 | C176: KEBUN GUNUNG MAS | D176: 2 | E176: #N/A | F176: 51100608 | G176: Bi Keamanan | H176: 6.Lain-Lain | I176: -88777742
A177: KS | B177: 5E03 | C177: KEBUN SUNGAI DEKAN | D177: 2 | E177: GC Panen | F177: 51100064 | G177: Bi Konsumsi Kebut Op | H177: 3. Bahan | I177: 9627997
A178: KS | B178: 5E03 | C178: KEBUN SUNGAI DEKAN | D178: 2 | E178: GC Panen | F178: 51100064 | G178: Bi Konsumsi Kebut Op | H178: 6.Lain-Lain | I178: 19360000
A179: KS | B179: 5E03 | C179: KEBUN SUNGAI DEKAN | D179: 2 | E179: GC Panen | F179: 90042077 | G179: Asst. Premi Panen | H179: 1. Gaji | I179: 88048808
A180: KS | B180: 5E03 | C180: KEBUN SUNGAI DEKAN | D180: 2 | E180: GC Panen | F180: 90043001 | G180: Act Type E-LBR | H180: 1. Gaji | I180: 280829498
A181: KS | B181: 5E03 | C181: KEBUN SUNGAI DEKAN | D181: 2 | E181: GC Panen | F181: 90043000 | G181: Act Type E-SPV | H181: 1. Gaji | I181: 131201627
A182: KS | B182: 5E03 | C182: KEBUN SUNGAI DEKAN | D182: 2 | E182: GC Pemel | F182: 51100064 | G182: Bi Konsumsi Kebut Op | H182: 3. Bahan | I182: 2249500
A183: KS | B183: 5E03 | C183: KEBUN SUNGAI DEKAN | D183: 2 | E183: GC Pemel | F183: 90043001 | G183: Act Type E-LBR | H183: 1. Gaji | I183: 199925200
A184: KS | B184: 5E03 | C184: KEBUN SUNGAI DEKAN | D184: 2 | E184: GC Pemel | F184: 90043000 | G184: Act Type E-SPV | H184: 1. Gaji | I184: 29157697
A185: KS | B185: 5E03 | C185: KEBUN SUNGAI DEKAN | D185: 2 | E185: #N/A | F185: 51100608 | G185: Bi Keamanan | H185: 2. SPK | I185: 175235396
...

Sheet DB BTL
A1: Kode | B1: Plant | C1: Unit Kerja | D1: Period | E1: Kode CC | F1: CO Object Name | G1: Cost Element | H1: Cost element name | I1: Klasifikasi | J1: Nilai
A2: KR | B2: 5E06 | C2: KEBUN SINTANG | D2: 1 | E2: BT01 | F2: GAJI & BISOS KARPIM | G2: 51100401 | H2: Bi Gaji dan Tunjanga | I2: 1. Gaji | J2: 10104644
A3: KR | B3: 5E06 | C3: KEBUN SINTANG | D3: 1 | E3: BT01 | F3: GAJI & BISOS KARPIM | G3: 51100403 | H3: Biaya Tunjangan PPH | I3: 1. Gaji | J3: 224557
A4: KR | B4: 5E06 | C4: KEBUN SINTANG | D4: 1 | E4: BT01 | F4: GAJI & BISOS KARPIM | G4: 51100427 | H4: BPJS TK - Jaminan Pe | I4: 1. Gaji | J4: 136530
A5: KR | B5: 5E06 | C5: KEBUN SINTANG | D5: 1 | E5: BT01 | F5: GAJI & BISOS KARPIM | G5: 51100429 | H5: BPJS Kesehatan - Per | I5: 1. Gaji | J5: 341326
A6: KR | B6: 5E06 | C6: KEBUN SINTANG | D6: 1 | E6: BT01 | F6: GAJI & BISOS KARPIM | G6: 51100433 | H6: DAPENBUN - Perusahaa | I6: 1. Gaji | J6: 0
A7: KR | B7: 5E06 | C7: KEBUN SINTANG | D7: 1 | E7: BT01 | F7: GAJI & BISOS KARPIM | G7: 51100440 | H7: BPJS TK - Jaminan Ha | I7: 1. Gaji | J7: 252581
A8: KR | B8: 5E06 | C8: KEBUN SINTANG | D8: 1 | E8: BT01 | F8: GAJI & BISOS KARPIM | G8: 51100441 | H8: BPJS TK - Jaminan Ke | I8: 1. Gaji | J8: 36863
A9: KR | B9: 5E06 | C9: KEBUN SINTANG | D9: 1 | E9: BT01 | F9: GAJI & BISOS KARPIM | G9: 51100442 | H9: BPJS TK - Jaminan Ke | I9: 1. Gaji | J9: 20480
A10: KR | B10: 5E06 | C10: KEBUN SINTANG | D10: 1 | E10: BT02 | F10: GAJI & BISOS KARPEL | G10: 90043001 | H10: Act Type E-LBR | I10: 1. Gaji | J10: 5468500
A11: KR | B11: 5E06 | C11: KEBUN SINTANG | D11: 1 | E11: BT04 | F11: PEMEL BANGUNAN RUMAH | G11: 51100100 | H11: Bi Pemel. Rumah Dina | I11: 6.Lain-Lain | J11: 373000
A12: KR | B12: 5E06 | C12: KEBUN SINTANG | D12: 1 | E12: BT05 | F12: PEMEL B. PERUSAHAAN | G12: 51100101 | H12: Bi Pemel. Bangunan P | I12: 6.Lain-Lain | J12: 3125000
A13: KR | B13: 5E06 | C13: KEBUN SINTANG | D13: 1 | E13: BT05 | F13: PEMEL B. PERUSAHAAN | G13: 51100609 | H13: Bi Bahan Bakar | I13: 6.Lain-Lain | J13: 50000
... A3570: KS | B3570: 5E19 | C3570: KEBUN LONGKALI | D3570: 5 | E3570: BT10 | F3570: PAJAK BUMI &BANGUNAN | G3570: 51100633 | H3570: Bi PBB | I3570: 6.Lain-Lain | J3570: 112260417

Sheet Pivot Kontrol beban
G2: % | P2: %
G3: {=IFERROR(D3:D640/E3:E640*100,0)} -> 88.18358 | P3: {=IFERROR(M3:M640/N3:N640*100,0)} -> 100
G4: 72.55485 | P4: 100
G5: 80.383349 | P5: 100
G6: 89.973917 | P6: 100
G7: 100.00001 | P7: 100
G8: 127.07589 | P8: 100
G9: 95.205616 | P9: 100
G10: 96.829003 | P10: 100
G11: 144.57277 | P11: 100
G12: 515.57438 | P12: 100
G13: 0 | P13: 100
G14: 159.99747 | P14: 100
G15: 90.241809 | P15: 100
... G640: 0 | P640: 0

Sheet K-Act1
A1: PT. PERKEBUNAN NUSANTARA IV - REGINAL V
A2: MONITORING CAPAIAN BIAYA PRODUKSI
A3: =UPPER('Balin-A'!E5) -> BULAN MEI 2026
A5: No | B5: Uraian | C5: Ket | D5: Sat | E5: Unit Kerja
E6: Balin | F6: Kumai | G6: Sinta | H6: Lokal | I6: Jlh
A7: I. | B7: BIAYA PEMELIHARAAN TANAMAN
A8: 1 | B8: Gaji/Upah & Biaya Karpim Tanaman | C8: Bln Ini | D8: Rp.000 | E8: ='Balin-A'!$E$14/1000 -> 105921.18 | F8: ='Kumai-A'!$E$14/1000 -> 0 | G8: ='Sinta-A'!$E$14/1000 -> 24059.534 | H8: ='Lokal-A'!$E$14/1000 -> 0 | I8: =sum(E8:H8) -> 129980.71
C9: Bln Lalu | D9: Rp.000 | E9: ='Balin-A'!$F$14/1000 -> 725438.24 | F9: ='Kumai-A'!$F$14/1000 -> 0 | G9: ='Sinta-A'!$F$14/1000 -> 238057.74 | H9: ='Lokal-A'!$F$14/1000 -> 80487.721 | I9: =sum(E9:H9) -> 1043983.7
C10: Thn Lalu | D10: Rp.000 | E10: ='Balin-A'!$G$14/1000 -> 66095.992 | F10: ='Kumai-A'!$G$14/1000 -> 0 | G10: ='Sinta-A'!$G$14/1000 -> 18144.433 | H10: ='Lokal-A'!$G$14/1000 -> 0 | I10: =sum(E10:H10) -> 84240.425
C11: RKO | D11: Rp.000 | E11: ='Balin-A'!$H$14/1000 -> 65272.351 | F11: ='Kumai-A'!$H$14/1000 -> 0 | G11: ='Sinta-A'!$H$14/1000 -> 0 | H11: ='Lokal-A'!$H$14/1000 -> 0 | I11: =sum(E11:H11) -> 65272.351
C12: RKAP | D12: Rp.000 | E12: ='Balin-A'!$I$14/1000 -> 65272.351 | F12: ='Kumai-A'!$I$14/1000 -> 0 | G12: ='Sinta-A'!$I$14/1000 -> 0 | H12: ='Lokal-A'!$I$14/1000 -> 0 | I12: =sum(E12:H12) -> 65272.351
C14: %/tase Bln Ini thdp Bln Lalu | D14: % | E14: =IFERROR(E8/E9*100,0) -> 14.600992 | F14: =IFERROR(F8/F9*100,0) -> 0 | G14: =IFERROR(G8/G9*100,0) -> 10.106596 | H14: =IFERROR(H8/H9*100,0) -> 0 | I14: =IFERROR(I8/I9*100,0) -> 12.450454
C15: %/tase Bln Ini thdp Thn Lalu | D15: % | E15: =IFERROR(E8/E10*100,0) -> 160.25356 | F15: =IFERROR(F8/F10*100,0) -> 0 | G15: =IFERROR(G8/G10*100,0) -> 132.60009 | H15: =IFERROR(H8/H10*100,0) -> 0 | I15: =IFERROR(I8/I10*100,0) -> 154.29731
C16: %/tase Bln Ini thdp RKO | D16: % | E16: =IFERROR(E8/E11*100,0) -> 162.27572 | F16: =IFERROR(F8/F11*100,0) -> 0 | G16: =IFERROR(G8/G11*100,0) -> 0 | H16: =IFERROR(H8/H11*100,0) -> 0 | I16: =IFERROR(I8/I11*100,0) -> 199.13594
C17: %/tase Bln Ini thdp RKAP | D17: % | E17: =IFERROR(E8/E12*100,0) -> 162.27572 | F17: =IFERROR(F8/F12*100,0) -> 0 | G17: =IFERROR(G8/G12*100,0) -> 0 | H17: =IFERROR(H8/H12*100,0) -> 0 | I17: =IFERROR(I8/I12*100,0) -> 199.13594
A19: 2 | B19: Pemel jalan, jembatan, & saluran air | C19: Bln Ini | D19: Rp.000 | E19: ='Balin-A'!$E$32/1000 -> 31997.642 | F19: ='Kumai-A'!$E$32/1000 -> 0 | G19: ='Sinta-A'!$E$32/1000 -> 0 | H19: ='Lokal-A'!$E$32/1000 -> 0 | I19: =sum(E19:H19) -> 31997.642
C20: Bln Lalu | D20: Rp.000 | E20: ='Balin-A'!$F$32/1000 -> 26271.3 | F20: ='Kumai-A'!$F$32/1000 -> 0 | G20: ='Sinta-A'!$F$32/1000 -> 0 | H20: ='Lokal-A'!$F$32/1000 -> 0 | I20: =sum(E20:H20) -> 26271.3
C21: Thn Lalu | D21: Rp.000 | E21: ='Balin-A'!$G$32/1000 -> 23271.917 | F21: ='Kumai-A'!$G$32/1000 -> 0 | G21: ='Sinta-A'!$G$32/1000 -> 0 | H21: ='Lokal-A'!$G$32/1000 -> 0 | I21: =sum(E21:H21) -> 23271.917
C22: RKO | D22: Rp.000 | E22: ='Balin-A'!$H$32/1000 -> 160.172 | F22: ='Kumai-A'!$H$32/1000 -> 0 | G22: ='Sinta-A'!$H$32/1000 -> 0 | H22: ='Lokal-A'!$H$32/1000 -> 0 | I22: =sum(E22:H22) -> 160.172
C23: RKAP | D23: Rp.000 | E23: ='Balin-A'!$I$32/1000 -> 160.172 | F23: ='Kumai-A'!$I$32/1000 -> 0 | G23: ='Sinta-A'!$I$32/1000 -> 0 | H23: ='Lokal-A'!$I$32/1000 -> 0 | I23: =sum(E23:H23) -> 160.172
C25: %/tase Bln Ini thdp Bln Lalu | D25: % | E25: =IFERROR(E19/E20*100,0) -> 121.79695 | F25: =IFERROR(F19/F20*100,0) -> 0 | G25: =IFERROR(G19/G20*100,0) -> 0 | H25: =IFERROR(H19/H20*100,0) -> 0 | I25: =IFERROR(I19/I20*100,0) -> 121.79695
C26: %/tase Bln Ini thdp Thn Lalu | D26: % | E26: =IFERROR(E19/E21*100,0) -> 137.49465 | F26: =IFERROR(F19/F21*100,0) -> 0 | G26: =IFERROR(G19/G21*100,0) -> 0 | H26: =IFERROR(H19/H21*100,0) -> 0 | I26: =IFERROR(I19/I21*100,0) -> 137.49465
C27: %/tase Bln Ini thdp RKO | D27: % | E27: =IFERROR(E19/E22*100,0) -> 19977.051 | F27: =IFERROR(F19/F22*100,0) -> 0 | G27: =IFERROR(G19/G22*100,0) -> 0 | H27: =IFERROR(H19/H22*100,0) -> 0 | I27: =IFERROR(I19/I22*100,0) -> 19977.051
C28: %/tase Bln Ini thdp RKAP | D28: % | E28: =IFERROR(E19/E23*100,0) -> 19977.051 | F28: =IFERROR(F19/F23*100,0) -> 0 | G28: =IFERROR(G19/G23*100,0) -> 0 | H28: =IFERROR(H19/H23*100,0) -> 0 | I28: =IFERROR(I19/I23*100,0) -> 19977.051
A30: 3 | B30: Pemangkasan / Tunas | C30: Bln Ini | D30: Rp.000 | E30: ='Balin-A'!$E$34/1000 -> 0 | F30: ='Kumai-A'!$E$34/1000 -> 0 | G30: ='Sinta-A'!$E$34/1000 -> 0 | H30: ='Lokal-A'!$E$34/1000 -> 0 | I30: =sum(E30:H30) -> 0
C31: Bln Lalu | D31: Rp.000 | E31: ='Balin-A'!$F$34/1000 -> 0 | F31: ='Kumai-A'!$F$34/1000 -> 0 | G31: ='Sinta-A'!$F$34/1000 -> 0 | H31: ='Lokal-A'!$F$34/1000 -> 0 | I31: =sum(E31:H31) -> 0
C32: Thn Lalu | D32: Rp.000 | E32: ='Balin-A'!$G$34/1000 -> 0 | F32: ='Kumai-A'!$G$34/1000 -> 0 | G32: ='Sinta-A'!$G$34/1000 -> 0 | H32: ='Lokal-A'!$G$34/1000 -> 0 | I32: =sum(E32:H32) -> 0
C33: RKO | D33: Rp.000 | E33: ='Balin-A'!$H$34/1000 -> 0 | F33: ='Kumai-A'!$H$34/1000 -> 0 | G33: ='Sinta-A'!$H$34/1000 -> 0 | H33: ='Lokal-A'!$H$34/1000 -> 0 | I33: =sum(E33:H33) -> 0
C34: RKAP | D34: Rp.000 | E34: ='Balin-A'!$I$34/1000 -> 0 | F34: ='Kumai-A'!$I$34/1000 -> 0 | G34: ='Sinta-A'!$I$34/1000 -> 0 | H34: ='Lokal-A'!$I$34/1000 -> 0 | I34: =sum(E34:H34) -> 0
C36: %/tase Bln Ini thdp Bln Lalu | D36: % | E36: =IFERROR(E30/E31*100,0) -> 0 | F36: =IFERROR(F30/F31*100,0) -> 0 | G36: =IFERROR(G30/G31*100,0) -> 0 | H36: =IFERROR(H30/H31*100,0) -> 0 | I36: =IFERROR(I30/I31*100,0) -> 0
C37: %/tase Bln Ini thdp Thn Lalu | D37: % | E37: =IFERROR(E30/E32*100,0) -> 0 | F37: =IFERROR(F30/F32*100,0) -> 0 | G37: =IFERROR(G30/G32*100,0) -> 0 | H37: =IFERROR(H30/H32*100,0) -> 0 | I37: =IFERROR(I30/I32*100,0) -> 0
C38: %/tase Bln Ini thdp RKO | D38: % | E38: =IFERROR(E30/E33*100,0) -> 0 | F38: =IFERROR(F30/F33*100,0) -> 0 | G38: =IFERROR(G30/G33*100,0) -> 0 | H38: =IFERROR(H30/H33*100,0) -> 0 | I38: =IFERROR(I30/I33*100,0) -> 0
C39: %/tase Bln Ini thdp RKAP | D39: % | E39: =IFERROR(E30/E34*100,0) -> 0 | F39: =IFERROR(F30/F34*100,0) -> 0 | G39: =IFERROR(G30/G34*100,0) -> 0 | H39: =IFERROR(H30/H34*100,0) -> 0 | I39: =IFERROR(I30/I34*100,0) -> 0
A41: 4 | B41: Pengendalian Gulma | C41: Bln Ini | D41: Rp.000 | E41: ='Balin-A'!$E$45/1000 -> 81857.408 | F41: ='Kumai-A'!$E$45/1000 -> 0 | G41: ='Sinta-A'!$E$45/1000 -> 0 | H41: ='Lokal-A'!$E$45/1000 -> 0 | I41: =sum(E41:H41) -> 81857.408
C42: Bln Lalu | D42: Rp.000 | E42: ='Balin-A'!$F$45/1000 -> 39005.879 | F42: ='Kumai-A'!$F$45/1000 -> 0 | G42: ='Sinta-A'!$F$45/1000 -> 0 | H42: ='Lokal-A'!$F$45/1000 -> 0 | I42: =sum(E42:H42) -> 39005.879
C43: Thn Lalu | D43: Rp.000 | E43: ='Balin-A'!$G$45/1000 -> 46575.686 | F43: ='Kumai-A'!$G$45/1000 -> 0 | G43: ='Sinta-A'!$G$45/1000 -> 0 | H43: ='Lokal-A'!$G$45/1000 -> 0 | I43: =sum(E43:H43) -> 46575.686
C44: RKO | D44: Rp.000 | E44: ='Balin-A'!$H$45/1000 -> 78138.964 | F44: ='Kumai-A'!$H$45/1000 -> 0 | G44: ='Sinta-A'!$H$45/1000 -> 0 | H44: ='Lokal-A'!$H$45/1000 -> 0 | I44: =sum(E44:H44) -> 78138.964
C45: RKAP | D45: Rp.000 | E45: ='Balin-A'!$I$45/1000 -> 78138.964 | F45: ='Kumai-A'!$I$45/1000 -> 0 | G45: ='Sinta-A'!$I$45/1000 -> 0 | H45: ='Lokal-A'!$I$45/1000 -> 0 | I45: =sum(E45:H45) -> 78138.964
C47: %/tase Bln Ini thdp Bln Lalu | D47: % | E47: =IFERROR(E41/E42*100,0) -> 209.85915 | F47: =IFERROR(F41/F42*100,0) -> 0 | G47: =IFERROR(G41/G42*100,0) -> 0 | H47: =IFERROR(H41/H42*100,0) -> 0 | I47: =IFERROR(I41/I42*100,0) -> 209.85915
C48: %/tase Bln Ini thdp Thn Lalu | D48: % | E48: =IFERROR(E41/E43*100,0) -> 175.75137 | F48: =IFERROR(F41/F43*100,0) -> 0 | G48: =IFERROR(G41/G43*100,0) -> 0 | H48: =IFERROR(H41/H43*100,0) -> 0 | I48: =IFERROR(I41/I43*100,0) -> 175.75137
...

Sheet K-Act2
A1: PT. PERKEBUNAN NUSANTARA IV - REGINAL V
A2: MONITORING CAPAIAN BIAYA PRODUKSI
A3: =UPPER('Balin-A'!N5) -> SD BULAN MEI 2026
A5: No | B5: Uraian | C5: Ket | D5: Sat | E5: Unit Kerja
E6: Balin | F6: Kumai | G6: Sinta | H6: Lokal | I6: Jlh
A7: I. | B7: BIAYA PEMELIHARAAN TANAMAN
A8: 1 | B8: Gaji/Upah & Biaya Karpim Tanaman | C8: sd Bln Ini | D8: Rp.000 | E8: ='Balin-A'!$N$14/1000 -> 451311.53 | F8: ='Kumai-A'!$N$14/1000 -> 0 | G8: ='Sinta-A'!$N$14/1000 -> 113226.93 | H8: ='Lokal-A'!$N$14/1000 -> 0 | I8: =sum(E8:H8) -> 564538.45
C9: Bln Lalu | D9: Rp.000 | E9: ='Balin-A'!$F$14/1000 -> 725438.24 | F9: ='Kumai-A'!$F$14/1000 -> 0 | G9: ='Sinta-A'!$F$14/1000 -> 238057.74 | H9: ='Lokal-A'!$F$14/1000 -> 80487.721 | I9: =sum(E9:H9) -> 1043983.7
C10: Thn Lalu | D10: Rp.000 | E10: ='Balin-A'!$O$14/1000 -> 340571.67 | F10: ='Kumai-A'!$O$14/1000 -> 0 | G10: ='Sinta-A'!$O$14/1000 -> 85062.998 | H10: ='Lokal-A'!$O$14/1000 -> 0 | I10: =sum(E10:H10) -> 425634.67
C11: RKO | D11: Rp.000 | E11: ='Balin-A'!$P$14/1000 -> 332113.31 | F11: ='Kumai-A'!$P$14/1000 -> 0 | G11: ='Sinta-A'!$P$14/1000 -> 0 | H11: ='Lokal-A'!$P$14/1000 -> 0 | I11: =sum(E11:H11) -> 332113.31
C12: RKAP | D12: Rp.000 | E12: ='Balin-A'!$Q$14/1000 -> 332113.31 | F12: ='Kumai-A'!$Q$14/1000 -> 0 | G12: ='Sinta-A'!$Q$14/1000 -> 0 | H12: ='Lokal-A'!$Q$14/1000 -> 0 | I12: =sum(E12:H12) -> 332113.31
C14: %/tase sd Bln Ini thdp Bln Lalu | D14: % | E14: =IFERROR(E8/E9*100,0) -> 62.21226 | F14: =IFERROR(F8/F9*100,0) -> 0 | G14: =IFERROR(G8/G9*100,0) -> 47.562802 | H14: =IFERROR(H8/H9*100,0) -> 0 | I14: =IFERROR(I8/I9*100,0) -> 54.075409
C15: %/tase sd Bln Ini thdp Thn Lalu | D15: % | E15: =IFERROR(E8/E10*100,0) -> 132.51587 | F15: =IFERROR(F8/F10*100,0) -> 0 | G15: =IFERROR(G8/G10*100,0) -> 133.1095 | H15: =IFERROR(H8/H10*100,0) -> 0 | I15: =IFERROR(I8/I10*100,0) -> 132.63451
C16: %/tase sd Bln Ini thdp RKO | D16: % | E16: =IFERROR(E8/E11*100,0) -> 135.89083 | F16: =IFERROR(F8/F11*100,0) -> 0 | G16: =IFERROR(G8/G11*100,0) -> 0 | H16: =IFERROR(H8/H11*100,0) -> 0 | I16: =IFERROR(I8/I11*100,0) -> 169.98369
C17: %/tase sd Bln Ini thdp RKAP | D17: % | E17: =IFERROR(E8/E12*100,0) -> 135.89083 | F17: =IFERROR(F8/F12*100,0) -> 0 | G17: =IFERROR(G8/G12*100,0) -> 0 | H17: =IFERROR(H8/H12*100,0) -> 0 | I17: =IFERROR(I8/I12*100,0) -> 169.98369
A19: 2 | B19: Pemel jalan, jembatan, & saluran air | C19: sd Bln Ini | D19: Rp.000 | E19: ='Balin-A'!$N$32/1000 -> 140515.18 | F19: ='Kumai-A'!$N$32/1000 -> 0 | G19: ='Sinta-A'!$N$32/1000 -> 0 | H19: ='Lokal-A'!$N$32/1000 -> 0 | I19: =sum(E19:H19) -> 140515.18
C20: Bln Lalu | D20: Rp.000 | E20: ='Balin-A'!$F$32/1000 -> 26271.3 | F20: ='Kumai-A'!$F$32/1000 -> 0 | G20: ='Sinta-A'!$F$32/1000 -> 0 | H20: ='Lokal-A'!$F$32/1000 -> 0 | I20: =sum(E20:H20) -> 26271.3
C21: Thn Lalu | D21: Rp.000 | E21: ='Balin-A'!$O$32/1000 -> 139115.97 | F21: ='Kumai-A'!$O$32/1000 -> 0 | G21: ='Sinta-A'!$O$32/1000 -> 0 | H21: ='Lokal-A'!$O$32/1000 -> 0 | I21: =sum(E21:H21) -> 139115.97
C22: RKO | D22: Rp.000 | E22: ='Balin-A'!$P$32/1000 -> 790.849 | F22: ='Kumai-A'!$P$32/1000 -> 0 | G22: ='Sinta-A'!$P$32/1000 -> 0 | H22: ='Lokal-A'!$P$32/1000 -> 0 | I22: =sum(E22:H22) -> 790.849
C23: RKAP | D23: Rp.000 | E23: ='Balin-A'!$Q$32/1000 -> 790.849 | F23: ='Kumai-A'!$Q$32/1000 -> 0 | G23: ='Sinta-A'!$Q$32/1000 -> 0 | H23: ='Lokal-A'!$Q$32/1000 -> 0 | I23: =sum(E23:H23) -> 790.849
C25: %/tase sd Bln Ini thdp Bln Lalu | D25: % | E25: =IFERROR(E19/E20*100,0) -> 534.86193 | F25: =IFERROR(F19/F20*100,0) -> 0 | G25: =IFERROR(G19/G20*100,0) -> 0 | H25: =IFERROR(H19/H20*100,0) -> 0 | I25: =IFERROR(I19/I20*100,0) -> 534.86193
C26: %/tase sd Bln Ini thdp Thn Lalu | D26: % | E26: =IFERROR(E19/E21*100,0) -> 101.00579 | F26: =IFERROR(F19/F21*100,0) -> 0 | G26: =IFERROR(G19/G21*100,0) -> 0 | H26: =IFERROR(H19/H21*100,0) -> 0 | I26: =IFERROR(I19/I21*100,0) -> 101.00579
C27: %/tase sd Bln Ini thdp RKO | D27: % | E27: =IFERROR(E19/E22*100,0) -> 17767.637 | F27: =IFERROR(F19/F22*100,0) -> 0 | G27: =IFERROR(G19/G22*100,0) -> 0 | H27: =IFERROR(H19/H22*100,0) -> 0 | I27: =IFERROR(I19/I22*100,0) -> 17767.637
C28: %/tase sd Bln Ini thdp RKAP | D28: % | E28: =IFERROR(E19/E23*100,0) -> 17767.637 | F28: =IFERROR(F19/F23*100,0) -> 0 | G28: =IFERROR(G19/G23*100,0) -> 0 | H28: =IFERROR(H19/H23*100,0) -> 0 | I28: =IFERROR(I19/I23*100,0) -> 17767.637
A30: 3 | B30: Pemangkasan / Tunas | C30: sd Bln Ini | D30: Rp.000 | E30: ='Balin-A'!$N$34/1000 -> 0 | F30: ='Kumai-A'!$N$34/1000 -> 0 | G30: ='Sinta-A'!$N$34/1000 -> 0 | H30: ='Lokal-A'!$N$34/1000 -> 0 | I30: =sum(E30:H30) -> 0
C31: Bln Lalu | D31: Rp.000 | E31: ='Balin-A'!$F$34/1000 -> 0 | F31: ='Kumai-A'!$F$34/1000 -> 0 | G31: ='Sinta-A'!$F$34/1000 -> 0 | H31: ='Lokal-A'!$F$34/1000 -> 0 | I31: =sum(E31:H31) -> 0
C32: Thn Lalu | D32: Rp.000 | E32: ='Balin-A'!$O$34/1000 -> 0 | F32: ='Kumai-A'!$O$34/1000 -> 0 | G32: ='Sinta-A'!$O$34/1000 -> 0 | H32: ='Lokal-A'!$O$34/1000 -> 0 | I32: =sum(E32:H32) -> 0
C33: RKO | D33: Rp.000 | E33: ='Balin-A'!$P$34/1000 -> 0 | F33: ='Kumai-A'!$P$34/1000 -> 0 | G33: ='Sinta-A'!$P$34/1000 -> 0 | H33: ='Lokal-A'!$P$34/1000 -> 0 | I33: =sum(E33:H33) -> 0
C34: RKAP | D34: Rp.000 | E34: ='Balin-A'!$Q$34/1000 -> 0 | F34: ='Kumai-A'!$Q$34/1000 -> 0 | G34: ='Sinta-A'!$Q$34/1000 -> 0 | H34: ='Lokal-A'!$Q$34/1000 -> 0 | I34: =sum(E34:H34) -> 0
C36: %/tase sd Bln Ini thdp Bln Lalu | D36: % | E36: =IFERROR(E30/E31*100,0) -> 0 | F36: =IFERROR(F30/F31*100,0) -> 0 | G36: =IFERROR(G30/G31*100,0) -> 0 | H36: =IFERROR(H30/H31*100,0) -> 0 | I36: =IFERROR(I30/I31*100,0) -> 0
C37: %/tase sd Bln Ini thdp Thn Lalu | D37: % | E37: =IFERROR(E30/E32*100,0) -> 0 | F37: =IFERROR(F30/F32*100,0) -> 0 | G37: =IFERROR(G30/G32*100,0) -> 0 | H37: =IFERROR(H30/H32*100,0) -> 0 | I37: =IFERROR(I30/I32*100,0) -> 0
C38: %/tase sd Bln Ini thdp RKO | D38: % | E38: =IFERROR(E30/E33*100,0) -> 0 | F38: =IFERROR(F30/F33*100,0) -> 0 | G38: =IFERROR(G30/G33*100,0) -> 0 | H38: =IFERROR(H30/H33*100,0) -> 0 | I38: =IFERROR(I30/I33*100,0) -> 0
C39: %/tase sd Bln Ini thdp RKAP | D39: % | E39: =IFERROR(E30/E34*100,0) -> 0 | F39: =IFERROR(F30/F34*100,0) -> 0 | G39: =IFERROR(G30/G34*100,0) -> 0 | H39: =IFERROR(H30/H34*100,0) -> 0 | I39: =IFERROR(I30/I34*100,0) -> 0
A41: 4 | B41: Pengendalian Gulma | C41: sd Bln Ini | D41: Rp.000 | E41: ='Balin-A'!$N$45/1000 -> 293519.5 | F41: ='Kumai-A'!$N$45/1000 -> 0 | G41: ='Sinta-A'!$N$45/1000 -> 0 | H41: ='Lokal-A'!$N$45/1000 -> 0 | I41: =sum(E41:H41) -> 293519.5
C42: Bln Lalu | D42: Rp.000 | E42: ='Balin-A'!$F$45/1000 -> 39005.879 | F42: ='Kumai-A'!$F$45/1000 -> 0 | G42: ='Sinta-A'!$F$45/1000 -> 0 | H42: ='Lokal-A'!$F$45/1000 -> 0 | I42: =sum(E42:H42) -> 39005.879
C43: Thn Lalu | D43: Rp.000 | E43: ='Balin-A'!$O$45/1000 -> 196256 | F43: ='Kumai-A'!$O$45/1000 -> 0 | G43: ='Sinta-A'!$O$45/1000 -> 134884 | H43: ='Lokal-A'!$O$45/1000 -> 0 | I43: =sum(E43:H43) -> 331140
C44: RKO | D44: Rp.000 | E44: ='Balin-A'!$P$45/1000 -> 479097.54 | F44: ='Kumai-A'!$P$45/1000 -> 0 | G44: ='Sinta-A'!$P$45/1000 -> 0 | H44: ='Lokal-A'!$P$45/1000 -> 0 | I44: =sum(E44:H44) -> 479097.54
C45: RKAP | D45: Rp.000 | E45: ='Balin-A'!$Q$45/1000 -> 479097.54 | F45: ='Kumai-A'!$Q$45/1000 -> 0 | G45: ='Sinta-A'!$Q$45/1000 -> 0 | H45: ='Lokal-A'!$Q$45/1000 -> 0 | I45: =sum(E45:H45) -> 479097.54
C47: %/tase sd Bln Ini thdp Bln Lalu | D47: % | E47: =IFERROR(E41/E42*100,0) -> 752.50068 | F47: =IFERROR(F41/F42*100,0) -> 0 | G47: =IFERROR(G41/G42*100,0) -> 0 | H47: =IFERROR(H41/H42*100,0) -> 0 | I47: =IFERROR(I41/I42*100,0) -> 752.50068
C48: %/tase sd Bln Ini thdp Thn Lalu | D48: % | E48: =IFERROR(E41/E43*100,0) -> 149.5595 | F48: =IFERROR(F41/F43*100,0) -> 0 | G48: =IFERROR(G41/G43*100,0) -> 0 | H48: =IFERROR(H41/H43*100,0) -> 0 | I48: =IFERROR(I41/I43*100,0) -> 88.639095
...

Sheet Plant
A1: Unit Kerja | B1: Plant | C1: Kode Sheet
A2: Kebun Gunung Meliau | B2: 5E01 | C2: Gunme-B
A3: Kebun Gunung Mas | B3: 5E02 | C3: Gumas-B
A4: Kebun Sungai Dekan | B4: 5E03 | C4: Dekan-B
A5: Kebun Rimba Belian | B5: 5E04 | C5: Rimba-B
A6: Kebun Sintang | B6: 5E06 | C6: Sinta-B
A7: Kebun Ngabang | B7: 5E07 | C7: Ngaba-B
A8: Kebun Parindu | B8: 5E08 | C8: Parin-B
A9: Kebun Kembayan | B9: 5E09 | C9: Bayan-B
A10: Kebun Danau Salak | B10: 5E11 | C10: Dasal-B
A11: Kebun Kumai | B11: 5E12 | C11: Kumai-B
A12: Kebun Batulicin | B12: 5E13 | C12: Balin-B
... A18: Kebun Longkali | B18: 5E19 | C18: Lokal-B
A19: Rekapitulasi

Sheet K-OHC1
A1: PT. PERKEBUNAN NUSANTARA IV - REGINAL V
A2: MONITORING CAPAIAN BIAYA TIDAK LANGSUNG
A3: =UPPER('Balin-A'!E5) -> BULAN MEI 2026
A5: No | B5: Uraian | C5: Ket | D5: Sat | E5: Unit Kerja
E6: Balin | F6: Kumai | G6: Sinta | H6: Lokal | I6: Jlh
A7: I. | B7: Biaya Tidak Langsung
A8: 1 | B8: Gaji dan Biaya Sosial Karpim | C8: Bln Ini | D8: Rp.000 | E8: ='Balin-A'!$E$167/1000 -> 74631.627 | F8: ='Kumai-A'!$E$167/1000 -> 0 | G8: ='Sinta-A'!$E$167/1000 -> 16895.706 | H8: ='Lokal-A'!$E$167/1000 -> 0 | I8: =sum(E8:H8) -> 91527.333
C9: Bln Lalu | D9: Rp.000 | E9: ='Balin-A'!$F$167/1000 -> 68837.3 | F9: ='Kumai-A'!$F$167/1000 -> 0 | G9: ='Sinta-A'!$F$167/1000 -> 15562.982 | H9: ='Lokal-A'!$F$167/1000 -> 0 | I9: =sum(E9:H9) -> 84400.282
C10: Thn Lalu | D10: Rp.000 | E10: ='Balin-A'!$G$167/1000 -> 44287.531 | F10: ='Kumai-A'!$G$167/1000 -> 0 | G10: ='Sinta-A'!$G$167/1000 -> 13422.542 | H10: ='Lokal-A'!$G$167/1000 -> 0 | I10: =sum(E10:H10) -> 57710.073
C11: RKO | D11: Rp.000 | E11: ='Balin-A'!$H$167/1000 -> 52674 | F11: ='Kumai-A'!$H$167/1000 -> 0 | G11: ='Sinta-A'!$H$167/1000 -> 0 | H11: ='Lokal-A'!$H$167/1000 -> 0 | I11: =sum(E11:H11) -> 52674
C12: RKAP | D12: Rp.000 | E12: ='Balin-A'!$I$167/1000 -> 52673.975 | F12: ='Kumai-A'!$I$167/1000 -> 0 | G12: ='Sinta-A'!$I$167/1000 -> 0 | H12: ='Lokal-A'!$I$167/1000 -> 0 | I12: =sum(E12:H12) -> 52673.975
C14: %/tase Bln Ini thdp Bln Lalu | D14: % | E14: =IFERROR(E8/E9*100,0) -> 108.41742 | F14: =IFERROR(F8/F9*100,0) -> 0 | G14: =IFERROR(G8/G9*100,0) -> 108.56342 | H14: =IFERROR(H8/H9*100,0) -> 0 | I14: =IFERROR(I8/I9*100,0) -> 108.44434
C15: %/tase Bln Ini thdp Thn Lalu | D15: % | E15: =IFERROR(E8/E10*100,0) -> 168.51612 | F15: =IFERROR(F8/F10*100,0) -> 0 | G15: =IFERROR(G8/G10*100,0) -> 125.87561 | H15: =IFERROR(H8/H10*100,0) -> 0 | I15: =IFERROR(I8/I10*100,0) -> 158.59854
C16: %/tase Bln Ini thdp RKO | D16: % | E16: =IFERROR(E8/E11*100,0) -> 141.68589 | F16: =IFERROR(F8/F11*100,0) -> 0 | G16: =IFERROR(G8/G11*100,0) -> 0 | H16: =IFERROR(H8/H11*100,0) -> 0 | I16: =IFERROR(I8/I11*100,0) -> 173.76188
C17: %/tase Bln Ini thdp RKAP | D17: % | E17: =IFERROR(E8/E12*100,0) -> 141.68596 | F17: =IFERROR(F8/F12*100,0) -> 0 | G17: =IFERROR(G8/G12*100,0) -> 0 | H17: =IFERROR(H8/H12*100,0) -> 0 | I17: =IFERROR(I8/I12*100,0) -> 173.76196
A19: 2 | B19: Gaji dan Biaya Sosial Karpel | C19: Bln Ini | D19: Rp.000 | E19: ='Balin-A'!$E$168/1000 -> 85750.216 | F19: ='Kumai-A'!$E$168/1000 -> 0 | G19: ='Sinta-A'!$E$168/1000 -> 7003.155 | H19: ='Lokal-A'!$E$168/1000 -> 0 | I19: =sum(E19:H19) -> 92753.371
C20: Bln Lalu | D20: Rp.000 | E20: ='Balin-A'!$F$168/1000 -> 66451.17 | F20: ='Kumai-A'!$F$168/1000 -> 0 | G20: ='Sinta-A'!$F$168/1000 -> 6287.35 | H20: ='Lokal-A'!$F$168/1000 -> 5709.408 | I20: =sum(E20:H20) -> 78447.928
C21: Thn Lalu | D21: Rp.000 | E21: ='Balin-A'!$G$168/1000 -> 70457.699 | F21: ='Kumai-A'!$G$168/1000 -> 0 | G21: ='Sinta-A'!$G$168/1000 -> 39395.376 | H21: ='Lokal-A'!$G$168/1000 -> 0 | I21: =sum(E21:H21) -> 109853.07
C22: RKO | D22: Rp.000 | E22: ='Balin-A'!$H$168/1000 -> 81717 | F22: ='Kumai-A'!$H$168/1000 -> 0 | G22: ='Sinta-A'!$H$168/1000 -> 0 | H22: ='Lokal-A'!$H$168/1000 -> 0 | I22: =sum(E22:H22) -> 81717
C23: RKAP | D23: Rp.000 | E23: ='Balin-A'!$I$168/1000 -> 81716.506 | F23: ='Kumai-A'!$I$168/1000 -> 0 | G23: ='Sinta-A'!$I$168/1000 -> 0 | H23: ='Lokal-A'!$I$168/1000 -> 0 | I23: =sum(E23:H23) -> 81716.506
C25: %/tase Bln Ini thdp Bln Lalu | D25: % | E25: =IFERROR(E19/E20*100,0) -> 129.04245 | F25: =IFERROR(F19/F20*100,0) -> 0 | G25: =IFERROR(G19/G20*100,0) -> 111.38484 | H25: =IFERROR(H19/H20*100,0) -> 0 | I25: =IFERROR(I19/I20*100,0) -> 118.23559
C26: %/tase Bln Ini thdp Thn Lalu | D26: % | E26: =IFERROR(E19/E21*100,0) -> 121.70454 | F26: =IFERROR(F19/F21*100,0) -> 0 | G26: =IFERROR(G19/G21*100,0) -> 17.776591 | H26: =IFERROR(H19/H21*100,0) -> 0 | I26: =IFERROR(I19/I21*100,0) -> 84.434023
C27: %/tase Bln Ini thdp RKO | D27: % | E27: =IFERROR(E19/E22*100,0) -> 104.93559 | F27: =IFERROR(F19/F22*100,0) -> 0 | G27: =IFERROR(G19/G22*100,0) -> 0 | H27: =IFERROR(H19/H22*100,0) -> 0 | I27: =IFERROR(I19/I22*100,0) -> 113.5056
C28: %/tase Bln Ini thdp RKAP | D28: % | E28: =IFERROR(E19/E23*100,0) -> 104.93622 | F28: =IFERROR(F19/F23*100,0) -> 0 | G28: =IFERROR(G19/G23*100,0) -> 0 | H28: =IFERROR(H19/H23*100,0) -> 0 | I28: =IFERROR(I19/I23*100,0) -> 113.50629
A30: 3 | B30: Biaya Perjalanan Dalam Kebun | C30: Bln Ini | D30: Rp.000 | E30: ='Balin-A'!$E$172/1000 -> 28306.05 | F30: ='Kumai-A'!$E$172/1000 -> 0 | G30: ='Sinta-A'!$E$172/1000 -> 0 | H30: ='Lokal-A'!$E$172/1000 -> 0 | I30: =sum(E30:H30) -> 28306.05
C31: Bln Lalu | D31: Rp.000 | E31: ='Balin-A'!$F$172/1000 -> 26237.103 | F31: ='Kumai-A'!$F$172/1000 -> 0 | G31: ='Sinta-A'!$F$172/1000 -> 0 | H31: ='Lokal-A'!$F$172/1000 -> 0 | I31: =sum(E31:H31) -> 26237.103
C32: Thn Lalu | D32: Rp.000 | E32: ='Balin-A'!$G$172/1000 -> 19698.252 | F32: ='Kumai-A'!$G$172/1000 -> 0 | G32: ='Sinta-A'!$G$172/1000 -> 3426.46 | H32: ='Lokal-A'!$G$172/1000 -> 0 | I32: =sum(E32:H32) -> 23124.712
C33: RKO | D33: Rp.000 | E33: ='Balin-A'!$H$172/1000 -> 22253 | F33: ='Kumai-A'!$H$172/1000 -> 0 | G33: ='Sinta-A'!$H$172/1000 -> 0 | H33: ='Lokal-A'!$H$172/1000 -> 0 | I33: =sum(E33:H33) -> 22253
C34: RKAP | D34: Rp.000 | E34: ='Balin-A'!$I$172/1000 -> 22252.551 | F34: ='Kumai-A'!$I$172/1000 -> 0 | G34: ='Sinta-A'!$I$172/1000 -> 0 | H34: ='Lokal-A'!$I$172/1000 -> 0 | I34: =sum(E34:H34) -> 22252.551
C36: %/tase Bln Ini thdp Bln Lalu | D36: % | E36: =IFERROR(E30/E31*100,0) -> 107.88558 | F36: =IFERROR(F30/F31*100,0) -> 0 | G36: =IFERROR(G30/G31*100,0) -> 0 | H36: =IFERROR(H30/H31*100,0) -> 0 | I36: =IFERROR(I30/I31*100,0) -> 107.88558
C37: %/tase Bln Ini thdp Thn Lalu | D37: % | E37: =IFERROR(E30/E32*100,0) -> 143.69828 | F37: =IFERROR(F30/F32*100,0) -> 0 | G37: =IFERROR(G30/G32*100,0) -> 0 | H37: =IFERROR(H30/H32*100,0) -> 0 | I37: =IFERROR(I30/I32*100,0) -> 122.40606
C38: %/tase Bln Ini thdp RKO | D38: % | E38: =IFERROR(E30/E33*100,0) -> 127.20105 | F38: =IFERROR(F30/F33*100,0) -> 0 | G38: =IFERROR(G30/G33*100,0) -> 0 | H38: =IFERROR(H30/H33*100,0) -> 0 | I38: =IFERROR(I30/I33*100,0) -> 127.20105
C39: %/tase Bln Ini thdp RKAP | D39: % | E39: =IFERROR(E30/E34*100,0) -> 127.20362 | F39: =IFERROR(F30/F34*100,0) -> 0 | G39: =IFERROR(G30/G34*100,0) -> 0 | H39: =IFERROR(H30/H34*100,0) -> 0 | I39: =IFERROR(I30/I34*100,0) -> 127.20362
A41: 4 | B41: Biaya Pemeliharaan Emplasmen | C41: Bln Ini | D41: Rp.000 | E41: ='Balin-A'!$E$174/1000 -> 0 | F41: ='Kumai-A'!$E$174/1000 -> 0 | G41: ='Sinta-A'!$E$174/1000 -> 0 | H41: ='Lokal-A'!$E$174/1000 -> 0 | I41: =sum(E41:H41) -> 0
C42: Bln Lalu | D42: Rp.000 | E42: ='Balin-A'!$F$174/1000 -> 0 | F42: ='Kumai-A'!$F$174/1000 -> 0 | G42: ='Sinta-A'!$F$174/1000 -> 0 | H42: ='Lokal-A'!$F$174/1000 -> 0 | I42: =sum(E42:H42) -> 0
C43: Thn Lalu | D43: Rp.000 | E43: ='Balin-A'!$G$174/1000 -> 0 | F43: ='Kumai-A'!$G$174/1000 -> 0 | G43: ='Sinta-A'!$G$174/1000 -> 0 | H43: ='Lokal-A'!$G$174/1000 -> 0 | I43: =sum(E43:H43) -> 0
C44: RKO | D44: Rp.000 | E44: ='Balin-A'!$H$174/1000 -> 0 | F44: ='Kumai-A'!$H$174/1000 -> 0 | G44: ='Sinta-A'!$H$174/1000 -> 0 | H44: ='Lokal-A'!$H$174/1000 -> 0 | I44: =sum(E44:H44) -> 0
C45: RKAP | D45: Rp.000 | E45: ='Balin-A'!$I$174/1000 -> 0 | F45: ='Kumai-A'!$I$174/1000 -> 0 | G45: ='Sinta-A'!$I$174/1000 -> 0 | H45: ='Lokal-A'!$I$174/1000 -> 0 | I45: =sum(E45:H45) -> 0
C47: %/tase Bln Ini thdp Bln Lalu | D47: % | E47: =IFERROR(E41/E42*100,0) -> 0 | F47: =IFERROR(F41/F42*100,0) -> 0 | G47: =IFERROR(G41/G42*100,0) -> 0 | H47: =IFERROR(H41/H42*100,0) -> 0 | I47: =IFERROR(I41/I42*100,0) -> 0
C48: %/tase Bln Ini thdp Thn Lalu | D48: % | E48: =IFERROR(E41/E43*100,0) -> 0 | F48: =IFERROR(F41/F43*100,0) -> 0 | G48: =IFERROR(G41/G43*100,0) -> 0 | H48: =IFERROR(H41/H43*100,0) -> 0 | I48: =IFERROR(I41/I43*100,0) -> 0
...

Sheet K-OHC2
A1: PT. PERKEBUNAN NUSANTARA IV - REGINAL V
A2: MONITORING CAPAIAN BIAYA TIDAK LANGSUNG
A3: =UPPER('Balin-A'!N5) -> SD BULAN MEI 2026
A5: No | B5: Uraian | C5: Ket | D5: Sat | E5: Unit Kerja
E6: Balin | F6: Kumai | G6: Sinta | H6: Lokal | I6: Jlh
A7: I. | B7: Biaya Tidak Langsung
A8: 1 | B8: Gaji dan Biaya Sosial Karpim | C8: sd Bln Ini | D8: Rp.000 | E8: ='Balin-A'!$N$167/1000 -> 328288.55 | F8: ='Kumai-A'!$N$167/1000 -> 0 | G8: ='Sinta-A'!$N$167/1000 -> 70005.756 | H8: ='Lokal-A'!$N$167/1000 -> 0 | I8: =sum(E8:H8) -> 398294.3
C9: Bln Lalu | D9: Rp.000 | E9: ='Balin-A'!$F$167/1000 -> 68837.3 | F9: ='Kumai-A'!$F$167/1000 -> 0 | G9: ='Sinta-A'!$F$167/1000 -> 15562.982 | H9: ='Lokal-A'!$F$167/1000 -> 0 | I9: =sum(E9:H9) -> 84400.282
C10: Thn Lalu | D10: Rp.000 | E10: ='Balin-A'!$O$167/1000 -> 228052.48 | F10: ='Kumai-A'!$O$167/1000 -> 0 | G10: ='Sinta-A'!$O$167/1000 -> 64840.554 | H10: ='Lokal-A'!$O$167/1000 -> 0 | I10: =sum(E10:H10) -> 292893.04
C11: RKO | D11: Rp.000 | E11: ='Balin-A'!$P$167/1000 -> 265339 | F11: ='Kumai-A'!$P$167/1000 -> 0 | G11: ='Sinta-A'!$P$167/1000 -> 0 | H11: ='Lokal-A'!$P$167/1000 -> 0 | I11: =sum(E11:H11) -> 265339
C12: RKAP | D12: Rp.000 | E12: ='Balin-A'!$Q$167/1000 -> 265339.18 | F12: ='Kumai-A'!$Q$167/1000 -> 0 | G12: ='Sinta-A'!$Q$167/1000 -> 0 | H12: ='Lokal-A'!$Q$167/1000 -> 0 | I12: =sum(E12:H12) -> 265339.18
C14: %/tase sd Bln Ini thdp Bln Lalu | D14: % | E14: =IFERROR(E8/E9*100,0) -> 476.90503 | F14: =IFERROR(F8/F9*100,0) -> 0 | G14: =IFERROR(G8/G9*100,0) -> 449.82225 | H14: =IFERROR(H8/H9*100,0) -> 0 | I14: =IFERROR(I8/I9*100,0) -> 471.9111
C15: %/tase sd Bln Ini thdp Thn Lalu | D15: % | E15: =IFERROR(E8/E10*100,0) -> 143.95307 | F15: =IFERROR(F8/F10*100,0) -> 0 | G15: =IFERROR(G8/G10*100,0) -> 107.96601 | H15: =IFERROR(H8/H10*100,0) -> 0 | I15: =IFERROR(I8/I10*100,0) -> 135.98626
C16: %/tase sd Bln Ini thdp RKO | D16: % | E16: =IFERROR(E8/E11*100,0) -> 123.7242 | F16: =IFERROR(F8/F11*100,0) -> 0 | G16: =IFERROR(G8/G11*100,0) -> 0 | H16: =IFERROR(H8/H11*100,0) -> 0 | I16: =IFERROR(I8/I11*100,0) -> 150.10771
C17: %/tase sd Bln Ini thdp RKAP | D17: % | E17: =IFERROR(E8/E12*100,0) -> 123.72411 | F17: =IFERROR(F8/F12*100,0) -> 0 | G17: =IFERROR(G8/G12*100,0) -> 0 | H17: =IFERROR(H8/H12*100,0) -> 0 | I17: =IFERROR(I8/I12*100,0) -> 150.10761
A19: 2 | B19: Gaji dan Biaya Sosial Karpel | C19: sd Bln Ini | D19: Rp.000 | E19: ='Balin-A'!$N$168/1000 -> 350658.56 | F19: ='Kumai-A'!$N$168/1000 -> 0 | G19: ='Sinta-A'!$N$168/1000 -> 31792.96 | H19: ='Lokal-A'!$N$168/1000 -> 8539.632 | I19: =sum(E19:H19) -> 390991.15
C20: Bln Lalu | D20: Rp.000 | E20: ='Balin-A'!$F$168/1000 -> 66451.17 | F20: ='Kumai-A'!$F$168/1000 -> 0 | G20: ='Sinta-A'!$F$168/1000 -> 6287.35 | H20: ='Lokal-A'!$F$168/1000 -> 5709.408 | I20: =sum(E20:H20) -> 78447.928
C21: Thn Lalu | D21: Rp.000 | E21: ='Balin-A'!$O$168/1000 -> 491220.35 | F21: ='Kumai-A'!$O$168/1000 -> 0 | G21: ='Sinta-A'!$O$168/1000 -> 249455.6 | H21: ='Lokal-A'!$O$168/1000 -> 0 | I21: =sum(E21:H21) -> 740675.95
C22: RKO | D22: Rp.000 | E22: ='Balin-A'!$P$168/1000 -> 421955 | F22: ='Kumai-A'!$P$168/1000 -> 0 | G22: ='Sinta-A'!$P$168/1000 -> 0 | H22: ='Lokal-A'!$P$168/1000 -> 0 | I22: =sum(E22:H22) -> 421955
C23: RKAP | D23: Rp.000 | E23: ='Balin-A'!$Q$168/1000 -> 421954.84 | F23: ='Kumai-A'!$Q$168/1000 -> 0 | G23: ='Sinta-A'!$Q$168/1000 -> 0 | H23: ='Lokal-A'!$Q$168/1000 -> 0 | I23: =sum(E23:H23) -> 421954.84
C25: %/tase sd Bln Ini thdp Bln Lalu | D25: % | E25: =IFERROR(E19/E20*100,0) -> 527.69358 | F25: =IFERROR(F19/F20*100,0) -> 0 | G25: =IFERROR(G19/G20*100,0) -> 505.6655 | H25: =IFERROR(H19/H20*100,0) -> 149.57123 | I25: =IFERROR(I19/I20*100,0) -> 498.40851
C26: %/tase sd Bln Ini thdp Thn Lalu | D26: % | E26: =IFERROR(E19/E21*100,0) -> 71.385186 | F26: =IFERROR(F19/F21*100,0) -> 0 | G26: =IFERROR(G19/G21*100,0) -> 12.744937 | H26: =IFERROR(H19/H21*100,0) -> 0 | I26: =IFERROR(I19/I21*100,0) -> 52.788423
C27: %/tase sd Bln Ini thdp RKO | D27: % | E27: =IFERROR(E19/E22*100,0) -> 83.103307 | F27: =IFERROR(F19/F22*100,0) -> 0 | G27: =IFERROR(G19/G22*100,0) -> 0 | H27: =IFERROR(H19/H22*100,0) -> 0 | I27: =IFERROR(I19/I22*100,0) -> 92.661813
C28: %/tase sd Bln Ini thdp RKAP | D28: % | E28: =IFERROR(E19/E23*100,0) -> 83.103338 | F28: =IFERROR(F19/F23*100,0) -> 0 | G28: =IFERROR(G19/G23*100,0) -> 0 | H28: =IFERROR(H19/H23*100,0) -> 0 | I28: =IFERROR(I19/I23*100,0) -> 92.661847
A30: 3 | B30: Biaya Perjalanan Dalam Kebun | C30: sd Bln Ini | D30: Rp.000 | E30: ='Balin-A'!$N$172/1000 -> 147391.47 | F30: ='Kumai-A'!$N$172/1000 -> 0 | G30: ='Sinta-A'!$N$172/1000 -> 8696.136 | H30: ='Lokal-A'!$N$172/1000 -> 0 | I30: =sum(E30:H30) -> 156087.61
C31: Bln Lalu | D31: Rp.000 | E31: ='Balin-A'!$F$172/1000 -> 26237.103 | F31: ='Kumai-A'!$F$172/1000 -> 0 | G31: ='Sinta-A'!$F$172/1000 -> 0 | H31: ='Lokal-A'!$F$172/1000 -> 0 | I31: =sum(E31:H31) -> 26237.103
C32: Thn Lalu | D32: Rp.000 | E32: ='Balin-A'!$O$172/1000 -> 104605.04 | F32: ='Kumai-A'!$O$172/1000 -> 0 | G32: ='Sinta-A'!$O$172/1000 -> 32079.987 | H32: ='Lokal-A'!$O$172/1000 -> 0 | I32: =sum(E32:H32) -> 136685.02
C33: RKO | D33: Rp.000 | E33: ='Balin-A'!$P$172/1000 -> 120878 | F33: ='Kumai-A'!$P$172/1000 -> 0 | G33: ='Sinta-A'!$P$172/1000 -> 0 | H33: ='Lokal-A'!$P$172/1000 -> 0 | I33: =sum(E33:H33) -> 120878
C34: RKAP | D34: Rp.000 | E34: ='Balin-A'!$Q$172/1000 -> 120878.14 | F34: ='Kumai-A'!$Q$172/1000 -> 0 | G34: ='Sinta-A'!$Q$172/1000 -> 0 | H34: ='Lokal-A'!$Q$172/1000 -> 0 | I34: =sum(E34:H34) -> 120878.14
C36: %/tase sd Bln Ini thdp Bln Lalu | D36: % | E36: =IFERROR(E30/E31*100,0) -> 561.76733 | F36: =IFERROR(F30/F31*100,0) -> 0 | G36: =IFERROR(G30/G31*100,0) -> 0 | H36: =IFERROR(H30/H31*100,0) -> 0 | I36: =IFERROR(I30/I31*100,0) -> 594.91176
C37: %/tase sd Bln Ini thdp Thn Lalu | D37: % | E37: =IFERROR(E30/E32*100,0) -> 140.90285 | F37: =IFERROR(F30/F32*100,0) -> 0 | G37: =IFERROR(G30/G32*100,0) -> 27.107667 | H37: =IFERROR(H30/H32*100,0) -> 0 | I37: =IFERROR(I30/I32*100,0) -> 114.19511
C38: %/tase sd Bln Ini thdp RKO | D38: % | E38: =IFERROR(E30/E33*100,0) -> 121.93408 | F38: =IFERROR(F30/F33*100,0) -> 0 | G38: =IFERROR(G30/G33*100,0) -> 0 | H38: =IFERROR(H30/H33*100,0) -> 0 | I38: =IFERROR(I30/I33*100,0) -> 129.12822
C39: %/tase sd Bln Ini thdp RKAP | D39: % | E39: =IFERROR(E30/E34*100,0) -> 121.93394 | F39: =IFERROR(F30/F34*100,0) -> 0 | G39: =IFERROR(G30/G34*100,0) -> 0 | H39: =IFERROR(H30/H34*100,0) -> 0 | I39: =IFERROR(I30/I34*100,0) -> 129.12807
A41: 4 | B41: Biaya Pemeliharaan Emplasmen | C41: sd Bln Ini | D41: Rp.000 | E41: ='Balin-A'!$N$174/1000 -> 200 | F41: ='Kumai-A'!$N$174/1000 -> 0 | G41: ='Sinta-A'!$N$174/1000 -> 0 | H41: ='Lokal-A'!$N$174/1000 -> 0 | I41: =sum(E41:H41) -> 200
C42: Bln Lalu | D42: Rp.000 | E42: ='Balin-A'!$F$174/1000 -> 0 | F42: ='Kumai-A'!$F$174/1000 -> 0 | G42: ='Sinta-A'!$F$174/1000 -> 0 | H42: ='Lokal-A'!$F$174/1000 -> 0 | I42: =sum(E42:H42) -> 0
C43: Thn Lalu | D43: Rp.000 | E43: ='Balin-A'!$O$174/1000 -> 0 | F43: ='Kumai-A'!$O$174/1000 -> 0 | G43: ='Sinta-A'!$O$174/1000 -> 0 | H43: ='Lokal-A'!$O$174/1000 -> 0 | I43: =sum(E43:H43) -> 0
C44: RKO | D44: Rp.000 | E44: ='Balin-A'!$P$174/1000 -> 0 | F44: ='Kumai-A'!$P$174/1000 -> 0 | G44: ='Sinta-A'!$P$174/1000 -> 0 | H44: ='Lokal-A'!$P$174/1000 -> 0 | I44: =sum(E44:H44) -> 0
C45: RKAP | D45: Rp.000 | E45: ='Balin-A'!$Q$174/1000 -> 0 | F45: ='Kumai-A'!$Q$174/1000 -> 0 | G45: ='Sinta-A'!$Q$174/1000 -> 0 | H45: ='Lokal-A'!$Q$174/1000 -> 0 | I45: =sum(E45:H45) -> 0
C47: %/tase sd Bln Ini thdp Bln Lalu | D47: % | E47: =IFERROR(E41/E42*100,0) -> 0 | F47: =IFERROR(F41/F42*100,0) -> 0 | G47: =IFERROR(G41/G42*100,0) -> 0 | H47: =IFERROR(H41/H42*100,0) -> 0 | I47: =IFERROR(I41/I42*100,0) -> 0
C48: %/tase sd Bln Ini thdp Thn Lalu | D48: % | E48: =IFERROR(E41/E43*100,0) -> 0 | F48: =IFERROR(F41/F43*100,0) -> 0 | G48: =IFERROR(G41/G43*100,0) -> 0 | H48: =IFERROR(H41/H43*100,0) -> 0 | I48: =IFERROR(I41/I43*100,0) -> 0
...

Sheet K-Prod1
A1: PT. PERKEBUNAN NUSANTARA IV - REGINAL V
A2: MONITORING CAPAIAN PRODUKSI
A3: =UPPER('Balin-A'!E5) -> BULAN MEI 2026
A5: No | B5: Uraian | C5: Ket | D5: Sat | E5: Unit Kerja
E6: Balin | F6: Kumai | G6: Sinta | H6: Lokal | I6: Jlh
A7: 1 | B7: Produksi | C7: Bln Ini | D7: Rp.000 | E7: ='Balin-B'!$F$20/1000 -> 38.407 | F7: ='Kumai-B'!$F$20/1000 -> 0 | G7: ='Sinta-B'!$F$20/1000 -> 0.387 | H7: ='Lokal-B'!$F$20/1000 -> 0.137 | I7: =sum(E7:H7) -> 38.931
C8: Bln Lalu | D8: Rp.000 | E8: 0 | F8: 0 | G8: 0 | H8: 0 | I8: =sum(E8:H8) -> 0
C9: Thn Lalu | D9: Rp.000 | E9: ='Balin-B'!$E$20/1000 -> 55.913 | F9: ='Kumai-B'!$E$20/1000 -> 0 | G9: ='Sinta-B'!$E$20/1000 -> 3.32 | H9: ='Lokal-B'!$E$20/1000 -> 0.35 | I9: =sum(E9:H9) -> 59.583
C10: RKO | D10: Rp.000 | E10: ='Balin-B'!$G$20/1000 -> 65.728 | F10: ='Kumai-B'!$G$20/1000 -> 0 | G10: ='Sinta-B'!$G$20/1000 -> 0 | H10: ='Lokal-B'!$G$20/1000 -> 0 | I10: =sum(E10:H10) -> 65.728
C11: RKAP | D11: Rp.000 | E11: ='Balin-B'!$H$20/1000 -> 65.728 | F11: ='Kumai-B'!$H$20/1000 -> 0 | G11: ='Sinta-B'!$H$20/1000 -> 0 | H11: ='Lokal-B'!$H$20/1000 -> 0 | I11: =sum(E11:H11) -> 65.728
C13: %/tase Bln Ini thdp Bln Lalu | D13: % | E13: =IFERROR(E7/E8*100,0) -> 0 | F13: =IFERROR(F7/F8*100,0) -> 0 | G13: =IFERROR(G7/G8*100,0) -> 0 | H13: =IFERROR(H7/H8*100,0) -> 0 | I13: =IFERROR(I7/I8*100,0) -> 0
C14: %/tase Bln Ini thdp Thn Lalu | D14: % | E14: =IFERROR(E7/E9*100,0) -> 68.690644 | F14: =IFERROR(F7/F9*100,0) -> 0 | G14: =IFERROR(G7/G9*100,0) -> 11.656627 | H14: =IFERROR(H7/H9*100,0) -> 39.142857 | I14: =IFERROR(I7/I9*100,0) -> 65.339107
C15: %/tase Bln Ini thdp RKO | D15: % | E15: =IFERROR(E7/E10*100,0) -> 58.43324 | F15: =IFERROR(F7/F10*100,0) -> 0 | G15: =IFERROR(G7/G10*100,0) -> 0 | H15: =IFERROR(H7/H10*100,0) -> 0 | I15: =IFERROR(I7/I10*100,0) -> 59.230465
C16: %/tase Bln Ini thdp RKAP | D16: % | E16: =IFERROR(E7/E11*100,0) -> 58.43324 | F16: =IFERROR(F7/F11*100,0) -> 0 | G16: =IFERROR(G7/G11*100,0) -> 0 | H16: =IFERROR(H7/H11*100,0) -> 0 | I16: =IFERROR(I7/I11*100,0) -> 59.230465

Sheet K-Prod2
A1: PT. PERKEBUNAN NUSANTARA IV - REGINAL V
A2: MONITORING CAPAIAN PRODUKSI
A3: =UPPER('Balin-A'!N5) -> SD BULAN MEI 2026
A5: No | B5: Uraian | C5: Ket | D5: Sat | E5: Unit Kerja
E6: Balin | F6: Kumai | G6: Sinta | H6: Lokal | I6: Jlh
A7: 1 | B7: Produksi | C7: sd Bln Ini | D7: Rp.000 | E7: ='Balin-B'!$J$20/1000 -> 206.338 | F7: ='Kumai-B'!$J$20/1000 -> 0 | G7: ='Sinta-B'!$J$20/1000 -> 3.115 | H7: ='Lokal-B'!$J$20/1000 -> 0.604 | I7: =sum(E7:H7) -> 210.057
C8: Bln Lalu | D8: Rp.000 | E8: 0 | F8: 0 | G8: 0 | H8: 0 | I8: =sum(E8:H8) -> 0
C9: Thn Lalu | D9: Rp.000 | E9: ='Balin-B'!$I$20/1000 -> 272.203 | F9: ='Kumai-B'!$I$20/1000 -> 0 | G9: ='Sinta-B'!$I$20/1000 -> 14.3 | H9: ='Lokal-B'!$I$20/1000 -> 1.641 | I9: =sum(E9:H9) -> 288.144
C10: RKO | D10: Rp.000 | E10: ='Balin-B'!$K$20/1000 -> 387.091 | F10: ='Kumai-B'!$K$20/1000 -> 0 | G10: ='Sinta-B'!$K$20/1000 -> 0 | H10: ='Lokal-B'!$K$20/1000 -> 0 | I10: =sum(E10:H10) -> 387.091
C11: RKAP | D11: Rp.000 | E11: ='Balin-B'!$L$20/1000 -> 387.0908 | F11: ='Kumai-B'!$L$20/1000 -> 0 | G11: ='Sinta-B'!$L$20/1000 -> 0 | H11: ='Lokal-B'!$L$20/1000 -> 0 | I11: =sum(E11:H11) -> 387.0908
C13: %/tase Bln Ini thdp Bln Lalu | D13: % | E13: =IFERROR(E7/E8*100,0) -> 0 | F13: =IFERROR(F7/F8*100,0) -> 0 | G13: =IFERROR(G7/G8*100,0) -> 0 | H13: =IFERROR(H7/H8*100,0) -> 0 | I13: =IFERROR(I7/I8*100,0) -> 0
C14: %/tase Bln Ini thdp Thn Lalu | D14: % | E14: =IFERROR(E7/E9*100,0) -> 75.802985 | F14: =IFERROR(F7/F9*100,0) -> 0 | G14: =IFERROR(G7/G9*100,0) -> 21.783217 | H14: =IFERROR(H7/H9*100,0) -> 36.806825 | I14: =IFERROR(I7/I9*100,0) -> 72.900008
C15: %/tase Bln Ini thdp RKO | D15: % | E15: =IFERROR(E7/E10*100,0) -> 53.304778 | F15: =IFERROR(F7/F10*100,0) -> 0 | G15: =IFERROR(G7/G10*100,0) -> 0 | H15: =IFERROR(H7/H10*100,0) -> 0 | I15: =IFERROR(I7/I10*100,0) -> 54.265534
C16: %/tase Bln Ini thdp RKAP | D16: % | E16: =IFERROR(E7/E11*100,0) -> 53.304806 | F16: =IFERROR(F7/F11*100,0) -> 0 | G16: =IFERROR(G7/G11*100,0) -> 0 | H16: =IFERROR(H7/H11*100,0) -> 0 | I16: =IFERROR(I7/I11*100,0) -> 54.265563

Sheet Balin-A
B1: PT PERKEBUNAN NUSANTARA IV - RPC 5 | Z1: Bulan Ini | AA1: 5
B2: LAMPIRAN LM 14 | Z2: Bulan Lalu | AA2: =IF(AA1=1,12,AA1-1) -> 4
B3: Kebun | D3: Kebun Batulicin | E3: =VLOOKUP(D3,Plant!$A$2:$B$27,2,false) -> 5E13
B4: Kode Komodity | D4: KR | AB4: sd Bulan Lalu
B5: WBS/GL/CC | C5: URAIAN (DESC WBS DLL) | E5: =CONCATENATE("Bulan ",'Tahun Lalu'!D3," 2026") -> Bulan Mei 2026 | N5: =CONCATENATE("sd ",E5) -> sd Bulan Mei 2026
E6: Real Bulan Ini | F6: Real Bulan Lalu | G6: Real Tahun Lalu | H6: RKO | I6: RKAP | J6: Cap Real Bulan Ini thdp (%) | N6: Real sd Bulan Ini | O6: Real Tahun Lalu | P6: RKO | Q6: RKAP | R6: Cap Real Bulan Ini thdp (%) | V6: Real sd Bulan Ini | W6: Real Tahun Lalu | X6: RKO | Y6: RKAP | Z6: Cap Real Bulan Ini thdp (%)
J7: =F6 -> Real Bulan Lalu | K7: =G6 -> Real Tahun Lalu | L7: =H6 -> RKO | M7: =I6 -> RKAP | R7: =$O$6 -> Real Tahun Lalu | S7: =$P$6 -> RKO | T7: =$Q$6 -> RKAP | Z7: =$O$6 -> Real Tahun Lalu | AA7: =$P$6 -> RKO | AB7: =$Q$6 -> RKAP
D9: BIAYA TANAMAN
B10: 99-01 | C10: =CONCATENATE(if(D4="KS","SP","SR"),"01") -> SR01 | D10: Gaji/Upah dan Biaya Kary. Staf dari WBS | E10: =SUMIFS('DB BTL'!$J:$J,'DB BTL'!$E:$E,$C10,'DB BTL'!$A:$A,$D$4,'DB BTL'!$B:$B,$E$3,'DB BTL'!$D:$D,AA$1) -> 105921179 | F10: =SUMIFS('DB WBS'!$J:$J,'DB WBS'!$A:$A,$D$4,'DB WBS'!$D:$D,AA$2,'DB WBS'!$B:$B,$E$3,'DB WBS'!$E:$E,$B10) -> 725438240 | G10: =IFERROR(HLOOKUP($E$3,'Tahun Lalu'!$B$5:$V$158,MATCH(B10,'Tahun Lalu'!$B$5:$B$158,0),0),0) -> 66095992 | H10: =IFERROR(round(HLOOKUP('Tahun Lalu'!$D$3,RKO!$A$1:$P$171,MATCH(B10,RKO!$A$1:$A$171,0),0)*1000,0),0) -> 65272351 | I10: =IFERROR(round(HLOOKUP('Tahun Lalu'!$D$3,RKAP!$A$1:$P$171,MATCH(B10,RKAP!$A$1:$A$171,0),0)*1000,0),0) -> 65272351 | J10: =IFERROR(E10/F10*100,0) -> 14.600992 | K10: =IFERROR(E10/G10*100,0) -> 160.25356 | L10: =IFERROR(E10/H10*100,0) -> 162.27572 | M10: =IFERROR(E10/I10*100,0) -> 162.27572 | N10: =E10+V10 -> 451311525 | O10: =G10+W10 -> 340571671 | P10: =H10+X10 -> 332113312 | Q10: =I10+Y10 -> 332113312 | R10: =IFERROR(N10/O10*100,0) -> 132.51587 | S10: =IFERROR(N10/P10*100,0) -> 135.89083 | T10: =IFERROR(N10/Q10*100,0) -> 135.89083 | V10: =IFERROR(__xludf.DUMMYFUNCTION("IFERROR(IMPORTRANGE(Link!B1,CONCATENATE(VLOOKUP($E$3,Link!$A$30:$B$39,2,false),""!N10:Q236"")),0)"),3.45390346E8) -> 345390346 | W10: =IFERROR(__xludf.DUMMYFUNCTION("""COMPUTED_VALUE"""),2.74475679E8) -> 274475679 | X10: =IFERROR(__xludf.DUMMYFUNCTION("""COMPUTED_VALUE"""),2.66840961E8) -> 266840961 | Y10: =IFERROR(__xludf.DUMMYFUNCTION("""COMPUTED_VALUE"""),2.66840961E8) -> 266840961 | Z10: =IFERROR(V10/W10*100,0) -> 125.83641 | AA10: =IFERROR(V10/X10*100,0) -> 129.43678 | AB10: =IFERROR(V10/Y10*100,0) -> 129.43678
B11: 99-01. | D11: Gaji/Upah dan Biaya Kary. Pelaksana dari WBS | E11: =SUMIFS('DB WBS'!$J:$J,'DB WBS'!$A:$A,$D$4,'DB WBS'!$D:$D,AA$1,'DB WBS'!$B:$B,$E$3,'DB WBS'!$E:$E,$B11) -> 0 | F11: =SUMIFS('DB WBS'!$J:$J,'DB WBS'!$A:$A,$D$4,'DB WBS'!$D:$D,AA$2,'DB WBS'!$B:$B,$E$3,'DB WBS'!$E:$E,$B11) -> 0 | G11: =IFERROR(HLOOKUP($E$3,'Tahun Lalu'!$B$5:$V$158,MATCH(B11,'Tahun Lalu'!$B$5:$B$158,0),0),0) -> 0 | H11: =IFERROR(round(HLOOKUP('Tahun Lalu'!$D$3,RKO!$A$1:$P$171,MATCH(B11,RKO!$A$1:$A$171,0),0)*1000,0),0) -> 0 | I11: =IFERROR(round(HLOOKUP('Tahun Lalu'!$D$3,RKAP!$A$1:$P$171,MATCH(B11,RKAP!$A$1:$A$171,0),0)*1000,0),0) -> 0 | J11: =IFERROR(E11/F11*100,0) -> 0 | K11: =IFERROR(E11/G11*100,0) -> 0 | L11: =IFERROR(E11/H11*100,0) -> 0 | M11: =IFERROR(E11/I11*100,0) -> 0 | N11: =E11+V11 -> 0 | O11: =G11+W11 -> 0 | P11: =H11+X11 -> 0 | Q11: =I11+Y11 -> 0 | R11: =IFERROR(N11/O11*100,0) -> 0 | S11: =IFERROR(N11/P11*100,0) -> 0 | T11: =IFERROR(N11/Q11*100,0) -> 0 | V11: =IFERROR(__xludf.DUMMYFUNCTION("""COMPUTED_VALUE"""),0.0) -> 0 | W11: =IFERROR(__xludf.DUMMYFUNCTION("""COMPUTED_VALUE"""),0.0) -> 0 | X11: =IFERROR(__xludf.DUMMYFUNCTION("""COMPUTED_VALUE"""),0.0) -> 0 | Y11: =IFERROR(__xludf.DUMMYFUNCTION("""COMPUTED_VALUE"""),0.0) -> 0 | Z11: =IFERROR(V11/W11*100,0) -> 0 | AA11: =IFERROR(V11/X11*100,0) -> 0 | AB11: =IFERROR(V11/Y11*100,0) -> 0
D12: Gaji/Upah dan Biaya Kary. Staf dari CC | E12: =SUMIFS('DB WBS'!$J:$J,'DB WBS'!$A:$A,$D$4,'DB WBS'!$D:$D,AA$1,'DB WBS'!$B:$B,$E$3,'DB WBS'!$E:$E,$B12) -> 0 | F12: =SUMIFS('DB WBS'!$J:$J,'DB WBS'!$A:$A,$D$4,'DB WBS'!$D:$D,AA$2,'DB WBS'!$B:$B,$E$3,'DB WBS'!$E:$E,$B12) -> 0 | G12: =IFERROR(HLOOKUP($E$3,'Tahun Lalu'!$B$5:$V$158,MATCH(B12,'Tahun Lalu'!$B$5:$B$158,0),0),0) -> 0 | H12: =IFERROR(round(HLOOKUP('Tahun Lalu'!$D$3,RKO!$A$1:$P$171,MATCH(B12,RKO!$A$1:$A$171,0),0)*1000,0),0) -> 0 | I12: =IFERROR(round(HLOOKUP('Tahun Lalu'!$D$3,RKAP!$A$1:$P$171,MATCH(B12,RKAP!$A$1:$A$171,0),0)*1000,0),0) -> 0 | J12: =IFERROR(E12/F12*100,0) -> 0 | K12: =IFERROR(E12/G12*100,0) -> 0 | L12: =IFERROR(E12/H12*100,0) -> 0 | M12: =IFERROR(E12/I12*100,0) -> 0 | N12: =E12+V12 -> 0 | O12: =G12+W12 -> 0 | P12: =H12+X12 -> 0 | Q12: =I12+Y12 -> 0 | R12: =IFERROR(N12/O12*100,0) -> 0 | S12: =IFERROR(N12/P12*100,0) -> 0 | T12: =IFERROR(N12/Q12*100,0) -> 0 | V12: =IFERROR(__xludf.DUMMYFUNCTION("""COMPUTED_VALUE"""),0.0) -> 0 | W12: =IFERROR(__xludf.DUMMYFUNCTION("""COMPUTED_VALUE"""),0.0) -> 0 | X12: =IFERROR(__xludf.DUMMYFUNCTION("""COMPUTED_VALUE"""),0.0) -> 0 | Y12: =IFERROR(__xludf.DUMMYFUNCTION("""COMPUTED_VALUE"""),0.0) -> 0 | Z12: =IFERROR(V12/W12*100,0) -> 0 | AA12: =IFERROR(V12/X12*100,0) -> 0 | AB12: =IFERROR(V12/Y12*100,0) -> 0
D13: Gaji/Upah dan Biaya Kary. Pelaksana dari CC | E13: =SUMIFS('DB WBS'!$J:$J,'DB WBS'!$A:$A,$D$4,'DB WBS'!$D:$D,AA$1,'DB WBS'!$B:$B,$E$3,'DB WBS'!$E:$E,$B13) -> 0 | F13: =SUMIFS('DB WBS'!$J:$J,'DB WBS'!$A:$A,$D$4,'DB WBS'!$D:$D,AA$2,'DB WBS'!$B:$B,$E$3,'DB WBS'!$E:$E,$B13) -> 0 | G13: =IFERROR(HLOOKUP($E$3,'Tahun Lalu'!$B$5:$V$158,MATCH(B13,'Tahun Lalu'!$B$5:$B$158,0),0),0) -> 0 | H13: =IFERROR(round(HLOOKUP('Tahun Lalu'!$D$3,RKO!$A$1:$P$171,MATCH(B13,RKO!$A$1:$A$171,0),0)*1000,0),0) -> 0 | I13: =IFERROR(round(HLOOKUP('Tahun Lalu'!$D$3,RKAP!$A$1:$P$171,MATCH(B13,RKAP!$A$1:$A$171,0),0)*1000,0),0) -> 0 | J13: =IFERROR(E13/F13*100,0) -> 0 | K13: =IFERROR(E13/G13*100,0) -> 0 | L13: =IFERROR(E13/H13*100,0) -> 0 | M13: =IFERROR(E13/I13*100,0) -> 0 | N13: =E13+V13 -> 0 | O13: =G13+W13 -> 0 | P13: =H13+X13 -> 0 | Q13: =I13+Y13 -> 0 | R13: =IFERROR(N13/O13*100,0) -> 0 | S13: =IFERROR(N13/P13*100,0) -> 0 | T13: =IFERROR(N13/Q13*100,0) -> 0 | V13: =IFERROR(__xludf.DUMMYFUNCTION("""COMPUTED_VALUE"""),0.0) -> 0 | W13: =IFERROR(__xludf.DUMMYFUNCTION("""COMPUTED_VALUE"""),0.0) -> 0 | X13: =IFERROR(__xludf.DUMMYFUNCTION("""COMPUTED_VALUE"""),0.0) -> 0 | Y13: =IFERROR(__xludf.DUMMYFUNCTION("""COMPUTED_VALUE"""),0.0) -> 0 | Z13: =IFERROR(V13/W13*100,0) -> 0 | AA13: =IFERROR(V13/X13*100,0) -> 0 | AB13: =IFERROR(V13/Y13*100,0) -> 0
B14: Jumlah Gaji | E14: =SUM(E10:E13) -> 105921179 | F14: =SUM(F10:F13) -> 725438240 | G14: =SUM(G10:G13) -> 66095992 | H14: =SUM(H10:H13) -> 65272351 | I14: =SUM(I10:I13) -> 65272351 | J14: =IFERROR(E14/F14*100,0) -> 14.600992 | K14: =IFERROR(E14/G14*100,0) -> 160.25356 | L14: =IFERROR(E14/H14*100,0) -> 162.27572 | M14: =IFERROR(E14/I14*100,0) -> 162.27572 | N14: =SUM(N10:N13) -> 451311525 | O14: =SUM(O10:O13) -> 340571671 | P14: =SUM(P10:P13) -> 332113312 | Q14: =SUM(Q10:Q13) -> 332113312 | R14: =IFERROR(N14/O14*100,0) -> 132.51587 | S14: =IFERROR(N14/P14*100,0) -> 135.89083 | T14: =IFERROR(N14/Q14*100,0) -> 135.89083 | V14: =IFERROR(__xludf.DUMMYFUNCTION("""COMPUTED_VALUE"""),3.45390346E8) -> 345390346 | W14: =IFERROR(__xludf.DUMMYFUNCTION("""COMPUTED_VALUE"""),2.74475679E8) -> 274475679 | X14: =IFERROR(__xludf.DUMMYFUNCTION("""COMPUTED_VALUE"""),2.66840961E8) -> 266840961 | Y14: =IFERROR(__xludf.DUMMYFUNCTION("""COMPUTED_VALUE"""),2.66840961E8) -> 266840961 | Z14: =IFERROR(V14/W14*100,0) -> 125.83641 | AA14: =IFERROR(V14/X14*100,0) -> 129.43678 | AB14: =IFERROR(V14/Y14*100,0) -> 129.43678
